Workbook

Sheet Revenue Lead Sheet
A1: Evergreen Inc.
A2: Revenue Lead Sheet
A3: For the Year Ended December 31, 2024
A5: Colour Legend: | B5: ■ Blue = hardcoded input | D5: ■ Black = formula | F5: ■ Green = cross-sheet link
A7: GL Account # | B7: Account Name | C7: Revenue Stream (FS Caption) | D7: Current Year 2024 ($) | E7: Prior Year 2023 ($) | F7: $ Change (CY vs PY) | G7: % Change (CY vs PY)
A8: 800001 | B8: =VLOOKUP(A8,'Year-End TB'!$A:$F,2,0) -> Domestic Direct to Consumer Sales | C8: Domestic DTC Revenue | D8: =VLOOKUP(A8,'Year-End TB'!$A:$F,5,0)*-1 -> 23043496 | E8: =VLOOKUP(A8,'Prior Year TB'!$A:$F,5,0)*-1 -> 20580000 | F8: =D8-E8 -> 2463496 | G8: =IF(E8=0,"-",F8/ABS(E8)) -> 0.1197034
A9: 800002 | B9: =VLOOKUP(A9,'Year-End TB'!$A:$F,2,0) -> AZ Franchise Sales | C9: Domestic Franchise Revenue | D9: =VLOOKUP(A9,'Year-End TB'!$A:$F,5,0)*-1 -> 2229331 | E9: =VLOOKUP(A9,'Prior Year TB'!$A:$F,5,0)*-1 -> 2050000 | F9: =D9-E9 -> 179331 | G9: =IF(E9=0,"-",F9/ABS(E9)) -> 0.087478537
A10: 800003 | B10: =VLOOKUP(A10,'Year-End TB'!$A:$F,2,0) -> CA Franchise Sales | C10: Domestic Franchise Revenue | D10: =VLOOKUP(A10,'Year-End TB'!$A:$F,5,0)*-1 -> 5573328 | E10: =VLOOKUP(A10,'Prior Year TB'!$A:$F,5,0)*-1 -> 5105000 | F10: =D10-E10 -> 468328 | G10: =IF(E10=0,"-",F10/ABS(E10)) -> 0.091739079
A11: 800004 | B11: =VLOOKUP(A11,'Year-End TB'!$A:$F,2,0) -> NYC Franchise Sales | C11: Domestic Franchise Revenue | D11: =VLOOKUP(A11,'Year-End TB'!$A:$F,5,0)*-1 -> 2340798 | E11: =VLOOKUP(A11,'Prior Year TB'!$A:$F,5,0)*-1 -> 2048000 | F11: =D11-E11 -> 292798 | G11: =IF(E11=0,"-",F11/ABS(E11)) -> 0.14296777
A12: 800005 | B12: =VLOOKUP(A12,'Year-End TB'!$A:$F,2,0) -> International Direct to Consumer Sales | C12: International DTC Revenue | D12: =VLOOKUP(A12,'Year-End TB'!$A:$F,5,0)*-1 -> 1003199 | E12: =VLOOKUP(A12,'Prior Year TB'!$A:$F,5,0)*-1 -> 852000 | F12: =D12-E12 -> 151199 | G12: =IF(E12=0,"-",F12/ABS(E12)) -> 0.17746362
A13: 800006 | B13: =VLOOKUP(A13,'Year-End TB'!$A:$F,2,0) -> AUS Franchise Sales | C13: International Franchise Revenue | D13: =VLOOKUP(A13,'Year-End TB'!$A:$F,5,0)*-1 -> 2503381 | E13: =VLOOKUP(A13,'Prior Year TB'!$A:$F,5,0)*-1 -> 2205000 | F13: =D13-E13 -> 298381 | G13: =IF(E13=0,"-",F13/ABS(E13)) -> 0.13532018
A14: 800007 | B14: =VLOOKUP(A14,'Year-End TB'!$A:$F,2,0) -> NZ Franchise Sales | C14: International Franchise Revenue | D14: =VLOOKUP(A14,'Year-End TB'!$A:$F,5,0)*-1 -> 2071064 | E14: =VLOOKUP(A14,'Prior Year TB'!$A:$F,5,0)*-1 -> 1855000 | F14: =D14-E14 -> 216064 | G14: =IF(E14=0,"-",F14/ABS(E14)) -> 0.11647655
A15: 800008 | B15: =VLOOKUP(A15,'Year-End TB'!$A:$F,2,0) -> Investment income | C15: Investment Income | D15: =VLOOKUP(A15,'Year-End TB'!$A:$F,5,0)*-1 -> 3402096 | E15: =VLOOKUP(A15,'Prior Year TB'!$A:$F,5,0)*-1 -> 3105000 | F15: =D15-E15 -> 297096 | G15: =IF(E15=0,"-",F15/ABS(E15)) -> 0.095683092
A16: Total Revenue | D16: =SUM(D8:D15) -> 42166693 | E16: =SUM(E8:E15) -> 37800000 | F16: =D16-E16 -> 4366693 | G16: =IF(E16=0,"-",F16/ABS(E16)) -> 0.11552098

Sheet Year-End TB
A1: Evergreen Inc.
A2: Trial Balance Worksheet
A3: Year Ended December 31, 2024
A4: Chart of Account # | B4: Account Name | C4: Debit ($) | D4: Credit ($) | E4: Net ($) | F4: FS Caption
A5: 100001 | B5: TD Checking Account #9564 | C5: 2513545 | E5: 2513545 | F5: N/A
A6: 100002 | B6: TD Savings Account #8733 | C6: 1765738 | E6: 1765738 | F6: N/A
A7: 100003 | B7: Royal Bank of Canada Checking #286 | C7: 3962126 | E7: 3962126 | F7: N/A
A8: 100004 | B8: Petty Cash | C8: 1383 | E8: 1383 | F8: N/A
A9: 120000 | B9: Accounts receivable | C9: 4996958 | E9: 4996958 | F9: N/A
A10: 120001 | B10: Reserve for bad debts | D10: 5325000 | E10: -5325000 | F10: N/A
A11: 130001 | B11: Inventory | C11: 1335956 | E11: 1335956 | F11: N/A
A12: 140001 | B12: Prepaid insurance | C12: 22000 | E12: 22000 | F12: N/A
A13: 140002 | B13: Prepaid other expenses | C13: 91540 | E13: 91540 | F13: N/A
A14: 140003 | B14: Prepaid rent | C14: 15000 | E14: 15000 | F14: N/A
A15: 150003 | B15: Office supplies | C15: 5229 | E15: 5229 | F15: N/A
A16: 160001 | B16: Utility deposits | C16: 33000 | E16: 33000 | F16: N/A
A17: 170001 | B17: Notes receivable | C17: 4375000 | E17: 4375000 | F17: N/A
A18: 180001 | B18: Investments | C18: 14620000 | E18: 14620000 | F18: N/A
A19: 190001 | B19: Organization expense | C19: 2910819 | E19: 2910819 | F19: N/A
A20: 200000 | B20: Vehicles | C20: 2636860 | E20: 2636860 | F20: N/A
A21: 200001 | B21: Furniture and fixtures | C21: 2491451 | E21: 2491451 | F21: N/A
A22: 200002 | B22: Equipment | C22: 2749415 | E22: 2749415 | F22: N/A
... A24: 200004 | B24: Land | C24: 697470 | E24: 697470 | F24: N/A
A25: 210000 | B25: Accumulated depreciation - vehicles | D25: 3465559 | E25: -3465559 | F25: N/A
A26: 210001 | B26: Accumulated depreciation - F&F | D26: 5571502 | E26: -5571502 | F26: N/A
A27: 210002 | B27: Accumulated depreciation - equipment | D27: 3071883 | E27: -3071883 | F27: N/A
A28: 210003 | B28: Accumulated depreciation - buildings | D28: 1636960 | E28: -1636960 | F28: N/A
A29: 300000 | B29: Goodwill | C29: 1356642 | E29: 1356642 | F29: N/A
A30: 300001 | B30: Other intangible assets | C30: 4389321 | E30: 4389321 | F30: N/A
A31: 400000 | B31: Accounts payable | D31: 4708610 | E31: -4708610 | F31: N/A
A32: 400001 | B32: Sales tax payable | D32: 1327849 | E32: -1327849 | F32: N/A
A33: 400002 | B33: Federal withholding taxes payable | D33: 46144 | E33: -46144 | F33: N/A
A34: 400003 | B34: FICA taxes payable | D34: 61154 | E34: -61154 | F34: N/A
A35: 400004 | B35: State withholding taxes payable | D35: 26777 | E35: -26777 | F35: N/A
A36: 400005 | B36: Unemployment taxes payable | D36: 8895 | E36: -8895 | F36: N/A
A37: 500001 | B37: Accrued wages | D37: 49235 | E37: -49235 | F37: N/A
A38: 500002 | B38: Unearned revenue | D38: 468027 | E38: -468027 | F38: N/A
A39: 500003 | B39: Accrued income taxes | D39: 24272 | E39: -24272 | F39: N/A
A40: 600001 | B40: Credit card payable | D40: 68716 | E40: -68716 | F40: N/A
A41: 600002 | B41: Bank loan payable | D41: 2038196 | E41: -2038196 | F41: N/A
...

Sheet Prior Year TB
A1: Evergreen Inc.
A2: Trial Balance Worksheet
A3: Year Ended December 31, 2023
A4: Chart of Account # | B4: Account Name | C4: Debit ($) | D4: Credit ($) | E4: Net ($) | F4: FS Caption
A5: 100001 | B5: TD Checking Account #9564 | C5: 2513545 | E5: 2513545 | F5: N/A
A6: 100002 | B6: TD Savings Account #8733 | C6: 1765738 | E6: 1765738 | F6: N/A
A7: 100003 | B7: Royal Bank of Canada Checking #286 | C7: 3962126 | E7: 3962126 | F7: N/A
A8: 100004 | B8: Petty Cash | C8: 1383 | E8: 1383 | F8: N/A
A9: 120000 | B9: Accounts receivable | C9: 4996958 | E9: 4996958 | F9: N/A
A10: 120001 | B10: Reserve for bad debts | D10: 5325000 | E10: -5325000 | F10: N/A
A11: 130001 | B11: Inventory | C11: 1335956 | E11: 1335956 | F11: N/A
A12: 140001 | B12: Prepaid insurance | C12: 22000 | E12: 22000 | F12: N/A
A13: 140002 | B13: Prepaid other expenses | C13: 91540 | E13: 91540 | F13: N/A
A14: 140003 | B14: Prepaid rent | C14: 15000 | E14: 15000 | F14: N/A
A15: 150003 | B15: Office supplies | C15: 5229 | E15: 5229 | F15: N/A
A16: 160001 | B16: Utility deposits | C16: 33000 | E16: 33000 | F16: N/A
A17: 170001 | B17: Notes receivable | C17: 4375000 | E17: 4375000 | F17: N/A
A18: 180001 | B18: Investments | C18: 14620000 | E18: 14620000 | F18: N/A
A19: 190001 | B19: Organization expense | C19: 2910819 | E19: 2910819 | F19: N/A
A20: 200000 | B20: Vehicles | C20: 2636860 | E20: 2636860 | F20: N/A
A21: 200001 | B21: Furniture and fixtures | C21: 2491451 | E21: 2491451 | F21: N/A
A22: 200002 | B22: Equipment | C22: 2749415 | E22: 2749415 | F22: N/A
... A24: 200004 | B24: Land | C24: 697470 | E24: 697470 | F24: N/A
A25: 210000 | B25: Accumulated depreciation - vehicles | D25: 3465559 | E25: -3465559 | F25: N/A
A26: 210001 | B26: Accumulated depreciation - F&F | D26: 5571502 | E26: -5571502 | F26: N/A
A27: 210002 | B27: Accumulated depreciation - equipment | D27: 3071883 | E27: -3071883 | F27: N/A
A28: 210003 | B28: Accumulated depreciation - buildings | D28: 1636960 | E28: -1636960 | F28: N/A
A29: 300000 | B29: Goodwill | C29: 1356642 | E29: 1356642 | F29: N/A
A30: 300001 | B30: Other intangible assets | C30: 4389321 | E30: 4389321 | F30: N/A
A31: 400000 | B31: Accounts payable | D31: 4708610 | E31: -4708610 | F31: N/A
A32: 400001 | B32: Sales tax payable | D32: 1327849 | E32: -1327849 | F32: N/A
A33: 400002 | B33: Federal withholding taxes payable | D33: 46144 | E33: -46144 | F33: N/A
A34: 400003 | B34: FICA taxes payable | D34: 61154 | E34: -61154 | F34: N/A
A35: 400004 | B35: State withholding taxes payable | D35: 26777 | E35: -26777 | F35: N/A
A36: 400005 | B36: Unemployment taxes payable | D36: 8895 | E36: -8895 | F36: N/A
A37: 500001 | B37: Accrued wages | D37: 49235 | E37: -49235 | F37: N/A
A38: 500002 | B38: Unearned revenue | D38: 468027 | E38: -468027 | F38: N/A
A39: 500003 | B39: Accrued income taxes | D39: 24272 | E39: -24272 | F39: N/A
A40: 600001 | B40: Credit card payable | D40: 68716 | E40: -68716 | F40: N/A
A41: 600002 | B41: Bank loan payable | D41: 2038196 | E41: -2038196 | F41: N/A
...

Sheet Reconciliation
A1: Evergreen Inc.
A2: Revenue Reconciliation
A3: For the Year Ended December 31, 2024
A5: Purpose: This reconciliation uses SUMIF to tie revenue GL accounts to financial statement captions. Ties to the Year-End Trial Balance.
A7: Revenue Stream (FS Caption) | B7: Current Year 2024 ($) [SUMIF] | C7: Prior Year 2023 ($) [SUMIF] | D7: $ Change | E7: % Change | F7: Tie to Lead Sheet?
A8: Domestic DTC Revenue | B8: =SUMIF('Year-End TB'!$F:$F,A8,'Year-End TB'!$E:$E)*-1 -> 23043496 | C8: =SUMIF('Prior Year TB'!$F:$F,A8,'Prior Year TB'!$E:$E)*-1 -> 20580000 | D8: =B8-C8 -> 2463496 | E8: =IF(C8=0,"-",D8/ABS(C8)) -> 0.1197034 | F8: =IF(B8=('Revenue Lead Sheet'!D8),"✓ Agrees","✗ Variance") -> ✓ Agrees
A9: Domestic Franchise Revenue | B9: =SUMIF('Year-End TB'!$F:$F,A9,'Year-End TB'!$E:$E)*-1 -> 10143457 | C9: =SUMIF('Prior Year TB'!$F:$F,A9,'Prior Year TB'!$E:$E)*-1 -> 9203000 | D9: =B9-C9 -> 940457 | E9: =IF(C9=0,"-",D9/ABS(C9)) -> 0.10219026 | F9: =IF(B9=('Revenue Lead Sheet'!D9+'Revenue Lead Sheet'!D10+'Revenue Lead Sheet'!D11),"✓ Agrees","✗ Variance") -> ✓ Agrees
A10: International DTC Revenue | B10: =SUMIF('Year-End TB'!$F:$F,A10,'Year-End TB'!$E:$E)*-1 -> 1003199 | C10: =SUMIF('Prior Year TB'!$F:$F,A10,'Prior Year TB'!$E:$E)*-1 -> 852000 | D10: =B10-C10 -> 151199 | E10: =IF(C10=0,"-",D10/ABS(C10)) -> 0.17746362 | F10: =IF(B10=('Revenue Lead Sheet'!D12),"✓ Agrees","✗ Variance") -> ✓ Agrees
A11: International Franchise Revenue | B11: =SUMIF('Year-End TB'!$F:$F,A11,'Year-End TB'!$E:$E)*-1 -> 4574445 | C11: =SUMIF('Prior Year TB'!$F:$F,A11,'Prior Year TB'!$E:$E)*-1 -> 4060000 | D11: =B11-C11 -> 514445 | E11: =IF(C11=0,"-",D11/ABS(C11)) -> 0.12671059 | F11: =IF(B11=('Revenue Lead Sheet'!D13+'Revenue Lead Sheet'!D14),"✓ Agrees","✗ Variance") -> ✓ Agrees
A12: Investment Income | B12: =SUMIF('Year-End TB'!$F:$F,A12,'Year-End TB'!$E:$E)*-1 -> 3402096 | C12: =SUMIF('Prior Year TB'!$F:$F,A12,'Prior Year TB'!$E:$E)*-1 -> 3105000 | D12: =B12-C12 -> 297096 | E12: =IF(C12=0,"-",D12/ABS(C12)) -> 0.095683092 | F12: =IF(B12=('Revenue Lead Sheet'!D15),"✓ Agrees","✗ Variance") -> ✓ Agrees
A13: Total Revenue | B13: =SUM(B8:B12) -> 42166693 | C13: =SUM(C8:C12) -> 37800000 | D13: =B13-C13 -> 4366693 | E13: =IF(C13=0,"-",D13/ABS(C13)) -> 0.11552098 | F13: =IF(B13='Revenue Lead Sheet'!D16,"✓ Total Agrees","✗ Total Variance") -> ✓ Total Agrees
